Workbook
Name MobileInternet: data!$B$15:$B$16
Name HouseholdAccessories: data!$B$12:$B$14
Name Subcategory: data!$B$2:$B$30
Name Savings: data!$B$22:$B$25
Name Account: data!$E$2:$E$10
Name RentAndPaybill: data!$B$2:$B$7
Name Bazar: data!$B$8:$B$11
Name Donation: data!$B$27:$B$28
Name ExtraExpenses: data!$B$17:$B$21
Name SavingsAcc: data!$G$2:$G$6
Name DATESTATUS: LAMBDA(startdate, enddate, IF(TODAY()<startdate, "Start in "&(startdate-TODAY()), IF(TODAY()<=enddate, "Expire in "&(enddate-TODAY()), "Expired")))

Sheet January 25
B2: TOTAL | C2: =sum(C4:C34) -> 46600 | D2: =sum(D4:D34) -> 43050 | E2: GROUP | F2: IN-HAND | G2: =C2-D2-G5 -> 1855 | I2: =49500-J3 -> 8500 | J2: Estimated | K2: Cost | L2: Remaining
B3: Date | C3: Withdraw | D3: Cost | F3: In-Acc | G3: =49500 - C2 -> 2900 | I3: BUDGET | J3: =sum(J4:J17) -> 41000 | K3: =sum(K4:K17) -> 42730 | L3: =sum(L4:L17) -> 1850
B4: 45651 | C4: 11000 | D4: 10500 | E4: =sum(D4:D10) -> 28265 | F4: Mob. Bank | I4: Prev. Due | J4: =6000+2000+2000 -> 10000 | K4: =6000+4000 -> 10000 | L4: =J4-K4 -> 0
B5: 45652 | D5: =20+30+220 -> 270 | F5: bKash | G5: =500+2000-635-1510-200-250+2000-210 -> 1695 | I5: Home | J5: 12000 | K5: 10000 | L5: =J5-K5 -> 2000
B6: 45653 | C6: 6500 | D6: 6000 | I6: H. Rent | J6: 7000 | K6: 7000 | L6: =J6-K6 -> 0
B7: 45654 | C7: 10000 | D7: =60+110+250+50+130+7000+180+20+20 -> 7820 | I7: ext. exp | J7: 5000 | K7: =4100+180+100+450+50+500 -> 5380 | L7: =J7-K7 -> -380
B8: 45655 | D8: =35 -> 35 | I8: Internet & MS | J8: 2000 | K8: =200+250+635 -> 1085 | L8: =J8-K8 -> 915
B9: 45656 | C9: 2000 | D9: =15+200+20+10+635+1510 -> 2390 | I9: SAV_2.5 | J9: 0 | L9: =J9-K9 -> 0
B10: 45657 | D10: =1000+20+30+200 -> 1250 | I10: SAV_5 | J10: 0 | L10: =J10-K10 -> 0
B11: 45658 | D11: =20+10+15+200 -> 245 | E11: =sum(D11:D20) -> 13410 | F11: LEND FROM | G11: =sum(G12:G20) -> 0 | I11: EXT(DN&Med) | J11: 1000 | K11: =130+220+200+20+935+75+20+20 -> 1620 | L11: =J11-K11 -> -620
B12: 45659 | D12: =10+15 -> 25 | F12: Mess | I12: Food_Meal | J12: 2000 | K12: =260+180+200+100+245+290+20+550+200+35+20+20+50+80+240+40 -> 2530 | L12: =J12-K12 -> -530
B13: 45660 | D13: =100+20+15+15+245 -> 395 | I13: Travel | J13: 1000 | K13: =300+20+60+10+20+30+10+20+10+30+50+20+20+20+20+20+20+10+20 -> 710 | L13: =J13-K13 -> 290
B14: 45661 | C14: 10000 | D14: =290+15+20+20+2200 -> 2545 | I14: Tea & Others | J14: 1000 | K14: =30+110+40+40+35+15+30+15+15+30+15+20+15+30+15+15+50+75+15+55+15+15+15+50+35+30 -> 825 | L14: =J14-K14 -> 175
B15: 45662 | D15: =20+15+4000+250 -> 4285 | I15: Lend Given | K15: =290+1510+1000-2000+200 -> 1000
B16: 45663 | D16: =30+935 -> 965 | I16: Donation | K16: =200+20+110+50 -> 380
B17: 45664 | D17: 0 | I17: FixedCost | K17: 2200
B18: 45665 | D18: =10+15 -> 25
B19: 45666 | D19: =(250+300)+15+30 -> 595
B20: 45667 | C20: 4100 | D20: =4100+180+(15*3+5) -> 4330
B21: 45668 | D21: =200+50+450+15*5+75 -> 850 | E21: =sum(D21:D34) -> 1375 | F21: LEND TO | G21: =sum(G22:G34) -> 2560
B22: 45669 | D22: =100+20 -> 120 | F22: sakib | G22: 50
B23: 45670 | D23: =20+15 -> 35 | F23: Monir | G23: =1510+1000 -> 2510
B24: 45671 | D24: =20+55 -> 75
B25: 45672 | D25: =20+15 -> 35
B26: 45673 | D26: =20+15+35 -> 70
B27: 45674 | D27: =0-2000+200+290-235 -> -1745
B28: 45675 | D28: =20+15+20 -> 55
B29: 45676 | D29: =50+20+20+50 -> 140
B30: 45677 | D30: =20+100+10 -> 130
B31: 45678 | D31: =50+20+20+10+60 -> 160
B32: 45679 | C32: 3000 | D32: =30+15+180+35+50+210 -> 520
B33: 45680 | D33: =20+15 -> 35
B34: 45681 | D34: =(220+35+50)+(20+30+20+20+500) -> 895

Sheet Feb 25
B3: Transaction | D3: DAY | E3: Date | F3: TotalCost | G3: =Sum(F5:F40)+sum(G5:G40) -> 51393 | I3: FINANCIAL STATUS | K3: =J5+J6+J7+J8-J9 -> 4848 | M3: BUDGET | N3: =sum(N5:N18) -> 50485 | O3: =sum(O5:O18) -> 51393 | P3: =sum(P5:P18) -> -908
B4: Amount | C4: From--To | F4: From Cash | G4: From bKash | I4: Type | J4: Current Status | K4: Start with | M4: Field | N4: Budget | O4: Cost | P4: Remaining
C5: None | D5: sunday | E5: 45683 | F5: =10+10 -> 20 | I5: S_A/C | J5: {=K5 - sum(IF((C5:C40="S_A/C-->bKash")+(C5:C40="S_A/C-->Cash")+(C5:C40="S_A/C-->SonaliBU"), B5:B40, 0))} -> 621 | K5: =680+49500-14-15-15-15 -> 50121 | M5: prevDue | N5: 685 | O5: 685 | P5: =N5-O5 -> 0
C6: None | D6: monday | E6: 45684 | F6: =15+20+50 -> 85 | I6: bKash | J6: {=K6 - sum(G5:G40) + sum(IF((C5:C40="S_A/C-->bKash")+(C5:C40="givenLend-->bKash")+(C5:C40="Cash-->bKash")+(C5:C40="takenLend-->bKash"), B5:B40, 0)) - sum(IF((C5:C40="bKash-->givenLend")+(C5:C40="bKash-->Cash")+(C5:C40="bKash-->takenLend"), B5:B40, 0))} -> 162 | K6: =3723-9+20-19+35+10 -> 3760 | M6: home | N6: 30000 | O6: =5900+4800+1500+1300+400+1200+750+7000 -> 22850 | P6: =N6-O6 -> 7150
C7: None | D7: tuesday | E7: 45685 | F7: =20+30+15 -> 65 | I7: Cash | J7: {=K7 - sum(F5:F40) + sum(IF((C5:C40="S_A/C-->Cash")+(C5:C40="givenLend-->Cash")+(C5:C40="bKash-->Cash")+(C5:C40="takenLend-->Cash"), B5:B40, 0)) - sum(IF((C5:C40="Cash-->takenLend")+(C5:C40="Cash-->givenLend")+(C5:C40="Cash-->bKash"), B5:B40, 0))} -> 1650 | K7: 1860 | M7: hRent | N7: 7000 | O7: 7000 | P7: =N7-O7 -> 0
B8: 500 | C8: S_A/C-->SonaliBU | D8: wednesday | E8: 45686 | F8: =20 -> 20 | I8: givenLend | J8: {=K8 + sum(IF((C5:C40="bKash-->givenLend")+(C5:C40="Cash-->givenLend"), B5:B40, 0)) - sum(IF((C5:C40="givenLend-->bKash")+(C5:C40="givenLend-->Cash"), B5:B40, 0))} -> 2415 | K8: 1000 | M8: extExp | N8: 4500 | O8: =250+250+225+140+1890+350+1490+5250 -> 9845 | P8: =N8-O8 -> -5345
C9: None | D9: thursday | E9: 45687 | F9: =20+(30+125)+250 -> 425 | G9: 1500 | I9: takenLend | J9: {=K9 + sum(IF((C5:C40="takenLend-->Cash")+(C5:C40="takenLend-->bKash"), B5:B40, 0)) - sum(IF((C5:C40="Cash-->takenLend")+(C5:C40="bKash-->takenLend"), B5:B40, 0))} -> 0 | K9: 0 | M9: internet | N9: 1500 | O9: =150+150+250+30+298+30 -> 908 | P9: =N9-O9 -> 592
C10: None | D10: friday | E10: 45688 | F10: =30+40+35 -> 105 | I10: SonaliBank | J10: {=K10 + sum(IF((C5:C40="S_A/C-->SonaliBU"), B5:B40, 0))} -> 300 | K10: -200 | M10: sav_2.5 | N10: 2500 | O10: 2500 | P10: =N10-O10 -> 0
B11: 2000 | C11: bKash-->givenLend | D11: saturday | E11: 45689 | F11: =(15+20)+250+(410+20+10+20)+65+685+110 -> 1605 | H11: 2 | I11: Nagad | M11: sav_5 | N11: 0 | P11: =N11-O11 -> 0
B12: 585 | C12: givenLend-->Cash | D12: sunday | E12: 45690 | F12: =(15+20) -> 35 | M12: dailyNec | N12: 1000 | O12: =65+260+100+150+70+35+170+105+85 -> 1040 | P12: =N12-O12 -> -40
B13: 12000 | C13: S_A/C-->Cash | D13: monday | E13: 45691 | F13: =20 -> 20 | G13: =50+100 -> 150 | M13: food | N13: 1000 | O13: =10+70+30+35+20+90+50+20+20+40+80+20+70+30+20+40+30 -> 675 | P13: =N13-O13 -> 325
B14: 2500 | C14: S_A/C-->bKash | D14: tuesday | E14: 45692 | F14: =30+225 -> 255 | G14: 2500 | I14: LEND GIVEN TO | K14: =sum(K16:K21) -> 2415 | M14: travel | N14: 500 | O14: =10+20+20+20+40+10+700+375+700 -> 1895 | P14: =N14-O14 -> -1395
B15: 1000 | C15: S_A/C-->bKash | D15: wednesday | E15: 45693 | F15: =7000+15+90 -> 7105 | I15: Date | J15: Given To | K15: Amount | M15: tea | N15: 500 | O15: =15+15+155+30+35+35+30+15+15+45+45+30+15+15+15+50+45+30+15+30+35+45+60+15+15+15+30 -> 895 | P15: =N15-O15 -> -395
B16: 500 | C16: bKash-->Cash | D16: thursday | E16: 45694 | F16: =15+(75+120+65)+(30+20)+190 -> 515 | I16: prev | J16: Monir | K16: =1000-585 -> 415 | M16: lendGiven | N16: 0 | P16: =N16-O16 -> 0
B17: 10000 | C17: S_A/C-->Cash | D17: friday | E17: 45695 | F17: =(15*3)+20+(150+90)+(5900+4800+1500+1300+400) -> 14205 | H17: 2 | I17: 45689 | J17: Ayon | K17: 1000 | M17: donation | N17: 300 | O17: =1500+110+300+260+10 -> 2180 | P17: =N17-O17 -> -1880
B18: 1000 | C18: givenLend-->bKash | D18: saturday | E18: 45696 | F18: =(15*3)+20+30+100 -> 195 | H18: 2 | I18: 45712 | J18: Razib Shekh vai | K18: 1000 | M18: mess | N18: 1000 | O18: =460+190+240+30+540-540 -> 920 | P18: =N18-O18 -> 80
C19: None | D19: sunday | E19: 45697 | F19: =30+10 -> 40
C20: None | D20: monday | E20: 45698 | F20: =15+40 -> 55
B21: 10000 | C21: S_A/C-->Cash | D21: tuesday | E21: 45699 | F21: =80+20+50+15+70 -> 235
C22: None | D22: wednesday | E22: 45700 | F22: =300+15 -> 315 | G22: =700 -> 700
C23: None | D23: thursday | E23: 45701 | F23: =750+(15+80+80+200)+(30+20)+1200 -> 2375 | I23: LEND TAKEN FROM | K23: =sum(K25:K30) -> 0
B24: 1000 | C24: S_A/C-->bKash | D24: friday | E24: 45702 | F24: =7000 -> 7000 | G24: 150 | H24: 0 | I24: Date | J24: Taken From | K24: Amount
B25: 1000 | C25: bKash-->Cash | D25: saturday | E25: 45703 | F25: =(50+650)+(20+20+20+10+10)+(15*3)+(10+5+20) -> 860 | G25: 250 | H25: 0
C26: None | D26: sunday | E26: 45704 | F26: =15+15+20 -> 50
C27: None | D27: monday | E27: 45705 | F27: =15 -> 15 | G27: 30
C28: None | D28: tuesday | E28: 45706 | F28: =30+70 -> 100
C29: None | D29: wednesday | E29: 45707 | F29: 0
B30: 2000 | C30: S_A/C-->Cash | D30: thursday | E30: 45708 | F30: =140+(20+15) -> 175
B31: 1000 | C31: Cash-->givenLend | D31: friday | E31: 45709 | F31: =(30+15)+(30)+(180+360)-(540) -> 75 | H31: 0 | I31: done
B32: 1500 | C32: S_A/C-->bKash | D32: saturday | E32: 45710 | F32: =20+(15*4)+(70+30+70)+(260) -> 510 | G32: =298+30 -> 328 | H32: 0
B33: 5000 | C33: S_A/C-->Cash | D33: sunday | E33: 45711 | F33: =15+40+(1890+350)+105 -> 2400 | G33: =1490 -> 1490
B34: 4000 | C34: S_A/C-->Cash | D34: monday | E34: 45712 | F34: =5250+15+30+85+10 -> 5390
C35: None | D35: tuesday | E35: 45713 | F35: =15 -> 15
C36: None | D36: wednesday | E36: 45714 | F36: =30 -> 30
C37: None
C38: None
C39: None
C40: None

Sheet March 25
B3: T r a n s a c t i o n | F3: DAY | G3: Date | H3: TotalCost | I3: =Sum(H5:H40)+sum(I5:I40) -> 49467 | K3: FINANCIAL STATUS | M3: =L5+L6+L7 -> 4388 | O3: BUDGET | P3: =sum(P5:P18) -> 30000 | Q3: =sum(Q5:Q18) -> 49235 | R3: =sum(R5:R18) -> -19235
B4: Date | C4: Amount | D4: From--To | H4: From Cash | I4: From bKash | K4: Type | L4: Current Status | M4: Start with | O4: Field | P4: Budget | Q4: Cost | R4: Remaining
B5: 45714 | C5: 12000 | D5: S_A/C-->bKash | K5: S_A/C | L5: {=M5 - sum(IF((D5:D40="S_A/C-->bKash")+(D5:D40="S_A/C-->Cash")+(D5:D40="S_A/C-->SonaliBU"), C5:C40, 0))} -> 46 | M5: =621+49500-(15*5) -> 50046 | O5: prevDue | P5: 0 | R5: =P5-Q5 -> 0
B6: 45716 | C6: 2500 | D6: S_A/C-->bKash | K6: bKash | L6: {=M6 - sum(I5:I40) + sum(IF((D5:D40="S_A/C-->bKash")+(D5:D40="SonaliBU-->bKash")+(D5:D40="givenLend-->bKash")+(D5:D40="Cash-->bKash")+(D5:D40="takenLend-->bKash"), C5:C40, 0)) - sum(IF((D5:D40="bKash-->givenLend")+(D5:D40="bKash-->Cash")+(D5:D40="bKash-->takenLend"), C5:C40, 0))} -> 4952 | M6: =162-18 -> 144 | O6: home | P6: 10000 | Q6: =10200+10100 -> 20300 | R6: =P6-Q6 -> -10300
B7: 45716 | C7: 2500 | D7: S_A/C-->bKash | K7: Cash | L7: {=M7 - sum(H5:H40) + sum(IF((D5:D40="S_A/C-->Cash")+(D5:D40="givenLend-->Cash")+(D5:D40="bKash-->Cash")+(D5:D40="takenLend-->Cash"), C5:C40, 0)) - sum(IF((D5:D40="Cash-->takenLend")+(D5:D40="Cash-->givenLend")+(D5:D40="Cash-->bKash"), C5:C40, 0))} -> -610 | M7: =1630+520 -> 2150 | O7: hRent | P7: 7000 | Q7: 7000 | R7: =P7-Q7 -> 0
B8: 45717 | C8: 20000 | D8: S_A/C-->SonaliBU | K8: givenLend | L8: {=M8 + sum(IF((D5:D40="bKash-->givenLend")+(D5:D40="Cash-->givenLend")+(D5:D40="SonaliBU-->givenLend"), C5:C40, 0)) - sum(IF((D5:D40="givenLend-->bKash")+(D5:D40="givenLend-->Cash")+(D5:D40="givenLend-->SonaliBU"), C5:C40, 0))} -> 1000 | M8: =2415+75 -> 2490 | O8: extExp | P8: 5000 | Q8: =2440+180+160+1480+2190+4147 -> 10597 | R8: =P8-Q8 -> -5597
B9: 45720 | C9: 10000 | D9: S_A/C-->Cash | F9: thursday | G9: 45715 | H9: =30 -> 30 | I9: =10200+208 -> 10408 | K9: takenLend | L9: {=M9 + sum(IF((D5:D40="takenLend-->Cash")+(D5:D40="takenLend-->bKash"), C5:C40, 0)) - sum(IF((D5:D40="Cash-->takenLend")+(D5:D40="bKash-->takenLend"), C5:C40, 0))} -> 0 | M9: -15 | O9: internet | P9: 1200 | Q9: =208+297+300+225 -> 1030 | R9: =P9-Q9 -> 170
B10: 45722 | C10: 1000 | D10: givenLend-->bKash | F10: friday | G10: 45716 | H10: =(15*3+5) + 80 + 180 + 75 -> 385 | I10: =2500+2440 -> 4940 | J10: 1 | K10: SonaliBU | L10: {=M10 + sum(IF((D5:D40="S_A/C-->SonaliBU")+(D5:D40="givenLend-->SonaliBU"), C5:C40, 0)) - sum(IF((D5:D40="SonaliBU-->givenLend")+(D5:D40="SonaliBU-->bKash"), C5:C40, 0))} -> 290 | M10: =300 -> 300 | O10: sav_2.5 | P10: 2500 | Q10: 2500 | R10: =P10-Q10 -> 0
B11: 45724 | C11: 10010 | D11: SonaliBU-->givenLend | F11: saturday | G11: 45717 | H11: =30+(15*3+5)+(500+275+25)+(50) -> 930 | J11: 3 | K11: EximBank | L11: =M11 -> 507 | M11: 507 | O11: sav_5 | P11: 0 | R11: =P11-Q11 -> 0
B12: 45729 | C12: 3000 | D12: S_A/C-->Cash | F12: sunday | G12: 45718 | H12: =200+15 -> 215 | I12: =297 -> 297 | J12: 1 | K12: Nagad | L12: =M12 | O12: dailyNec | P12: 800 | Q12: =75+280+70+70 -> 495 | R12: =P12-Q12 -> 305
B13: 45730 | C13: 10000 | D13: SonaliBU-->bKash | F13: monday | G13: 45719 | H13: =15 -> 15 | J13: 1 | O13: food | P13: 700 | Q13: =80+30+50+30+80+140+35 -> 445 | R13: =P13-Q13 -> 255
B14: 45732 | C14: 1030 | D14: takenLend-->bKash | F14: tuesday | G14: 45720 | H14: =(180+240)+(280)+15+30 -> 745 | J14: 1 | O14: travel | P14: 300 | Q14: =90+30+1600+30 -> 1750 | R14: =P14-Q14 -> -1450
B15: 45732 | C15: 400 | D15: givenLend-->bKash | F15: wednesday | G15: 45721 | H15: =15 -> 15 | J15: 1 | K15: LEND GIVEN TO | M15: =sum(M17:M22) -> 1000 | O15: tea | P15: 500 | Q15: =30+50+50+15+15+15+15+15+15+5+17+15+17+15+52+50+15+40+15+15+15 -> 491 | R15: =P15-Q15 -> 9
B16: 45732 | C16: 1000 | D16: bKash-->Cash | F16: thursday | G16: 45722 | H16: =(10+50+30) -> 90 | J16: 1 | K16: Date | L16: Given To | M16: Amount | O16: lendGiven | P16: 0 | R16: =P16-Q16 -> 0
B17: 45735 | C17: 10000 | D17: givenLend-->bKash | F17: friday | G17: 45723 | H17: =(110+20)+15 -> 145 | J17: 1 | O17: donation | P17: 500 | Q17: =100+100 -> 200 | R17: =P17-Q17 -> 300
B18: 45736 | C18: 5100 | D18: bKash-->givenLend | F18: saturday | G18: 45724 | H18: =7000+(750+260)+15 -> 8025 | J18: 1 | O18: mess | P18: 1500 | Q18: =(180+220)+800+200+130+240+750+260+22+20+570+155+250+350-50+175+155 -> 4427 | R18: =P18-Q18 -> -2927
B19: 45740 | C19: 5200 | D19: givenLend-->bKash | F19: sunday | G19: 45725 | H19: =220+160+(22+20) -> 422 | J19: 1 | K19: 45712 | L19: Razib Shekh vai | M19: 1000
B20: 45740 | C20: 1015 | D20: bKash-->takenLend | F20: monday | G20: 45726 | H20: =30 -> 30 | J20: 1
D21: None | F21: tuesday | G21: 45727 | H21: =70+5 -> 75 | J21: 1
D22: None | F22: wednesday | G22: 45728 | H22: =(200+280+40+50)+15+2 -> 587 | J22: 1
D23: None | F23: thursday | G23: 45729 | H23: =(500+580+400) +15 +80 -> 1575 | J23: 1
D24: None | F24: friday | G24: 45730 | H24: =15+2 -> 17 | I24: 10100 | J24: 1 | K24: LEND TAKEN FROM | M24: =sum(M26:M31) -> 0
D25: None | F25: saturday | G25: 45731 | H25: 15 | J25: 1 | K25: Date | L25: Taken From | M25: Amount
D26: None | F26: sunday | G26: 45732 | H26: =1600+(35+15+2) -> 1652 | I26: =2190 -> 2190 | J26: 1
D27: None | F27: monday | G27: 45733 | H27: =15+2 -> 17 | J27: 1
D28: None | F28: tuesday | G28: 45734 | H28: =15+10 -> 25 | J28: 1
D29: None | F29: wednesday | G29: 45735 | H29: =15+(195+30+125)+100+35 -> 500 | J29: 2
D30: None | F30: thursday | G30: 45736 | H30: =(15+25)+(30+180+40-50) -> 240 | J30: 3
D31: None | F31: friday | G31: 45737 | H31: =(60+80) -> 140 | J31: 2
D32: None | F32: saturday | G32: 45738 | H32: =30+15 -> 45 | I32: =300+4147 -> 4447 | J32: 2
D33: None | F33: sunday | G33: 45739 | H33: =100+30+25+(35+15) -> 205 | J33: 2
D34: None | F34: monday | G34: 45740 | H34: =15+70 -> 85 | I34: =225+100 -> 325 | J34: 2
D35: None | F35: tuesday | G35: 45741 | H35: =15+(35+140) -> 190 | J35: 2
D36: None | F36: wednesday | G36: 45742 | H36: =60+15+70+200 -> 345 | J36: 1
D37: None
D38: None
D39: None
D40: None

Sheet Apr 25
B2: T r a n s a c t i o n | G2: DAY | H2: Date | I2: TotalCost | J2: =Sum(I4:I39)+sum(J4:J39) -> 52938 | L2: FINANCIAL STATUS | N2: =M4+M5+M6-M8 -> 4894 | P2: BUDGET | Q2: =sum(Q4:Q17) -> 40000 | R2: =sum(R4:R17) -> 52938 | S2: =sum(S4:S17) -> -12938 | U2: Total | W2: Date | X2: mess | Z2: tea | AB2: food | AD2: dailyNec | AF2: internet | AH2: extExp | AJ2: travel | AL2: home | AN2: hRent | AP2: sav_2.5 | AR2: donation | AT2: prevDue
B3: Date | C3: Cost | D3: Amount | E3: From--To | I3: Cash | J3: bKash | L3: Type | M3: Current Status | N3: Start with | P3: Field | Q3: Budget | R3: Cost | S3: Remaining | U3: Cash | V3: bKash | X3: Cash | Y3: bKash | Z3: Cash | AA3: bKash | AB3: Cash | AC3: bKash | AD3: Cash | AE3: bKash | AF3: Cash | AG3: bKash | AH3: Cash | AI3: bKash | AJ3: Cash | AK3: bKash | AL3: Cash | AM3: bKash | AN3: Cash | AO3: bKash | AP3: Cash | AQ3: bKash | AR3: Cash | AS3: bKash | AT3: Cash | AU3: bKash
B4: 45740 | D4: 49500 | E4: add-->S_A/C | G4: wednesday | H4: 45742 | I4: =X4+Z4+AB4+AD4+AF4+AH4+AJ4+AL4+AN4+AP4+AR4+AT4 -> 1500 | J4: =Y4+AA4+AC4+AE4+AG4+AI4+AK4+AM4+AO4+AQ4+AS4+AU4 -> 2500 | L4: S_A/C | M4: {=N4 - sum(IF((E4:E39="S_A/C-->bKash")+(E4:E39="S_A/C-->Cash")+(E4:E39="S_A/C-->SonaliBU"), D4:D39, 0)) + sum(IF((E4:E39="add-->S_A/C"), D4:D39, 0)) - sum(IF((E4:E39="S_A/C-->Cash"), C4:C39, 0))} -> 822 | N4: ='March 25'!L5 -> 46 | P4: prevDue | Q4: 0 | R4: =sum(AT4:AT39)+sum(AU4:AU39) -> 0 | S4: =Q4-R4 -> 0 | U4: =X4+Z4+AB4+AD4+AF4+AH4+AJ4+AL4+AN4+AP4+AR4+AT4 -> 1500 | V4: =Y4+AA4+AC4+AE4+AG4+AI4+AK4+AM4+AO4+AQ4+AS4+AU4 -> 2500 | W4: =IF(H4<>"", TEXT(H4, "DD/MM/YY"), "") -> 26/03/25 | AN4: 1500 | AQ4: 2500
B5: 45740 | C5: 15 | D5: 10000 | E5: S_A/C-->Cash | G5: thursday | H5: 45743 | I5: =X5+Z5+AB5+AD5+AF5+AH5+AJ5+AL5+AN5+AP5+AR5+AT5 -> 1200 | J5: =Y5+AA5+AC5+AE5+AG5+AI5+AK5+AM5+AO5+AQ5+AS5+AU5 -> 0 | L5: bKash | M5: {=N5 - sum(J4:J39) + sum(IF((E4:E39="S_A/C-->bKash")+(E4:E39="givenLend-->bKash")+(E4:E39="Cash-->bKash")+(E4:E39="takenLend-->bKash")+(E4:E39="add-->bKash"), D4:D39, 0)) - sum(IF((E4:E39="bKash-->givenLend")+(E4:E39="bKash-->Cash")+(E4:E39="bKash-->takenLend"), D4:D39, 0))} -> 314 | N5: ='March 25'!L6 -> 4952 | P5: home | Q5: 10000 | R5: =sum(AL4:AL39)+sum(AM4:AM39) -> 17190 | S5: =Q5-R5 -> -7190 | U5: =X5+Z5+AB5+AD5+AF5+AH5+AJ5+AL5+AN5+AP5+AR5+AT5 -> 1200 | V5: =Y5+AA5+AC5+AE5+AG5+AI5+AK5+AM5+AO5+AQ5+AS5+AU5 -> 0 | W5: =IF(H5<>"", TEXT(H5, "DD/MM/YY"), "") -> 27/03/25 | Z5: =15+15+15 -> 45 | AB5: =300+45 -> 345 | AD5: 10 | AJ5: =200+120+120 -> 440 | AL5: =300 -> 300 | AR5: =20+40 -> 60
B6: 45741 | D6: 129 | E6: add-->bKash | G6: friday | H6: 45744 | I6: =X6+Z6+AB6+AD6+AF6+AH6+AJ6+AL6+AN6+AP6+AR6+AT6 -> 9145 | J6: =Y6+AA6+AC6+AE6+AG6+AI6+AK6+AM6+AO6+AQ6+AS6+AU6 -> 200 | L6: Cash | M6: {=N6 - sum(I4:I39) + sum(IF((E4:E39="S_A/C-->Cash")+(E4:E39="givenLend-->Cash")+(E4:E39="bKash-->Cash")+(E4:E39="takenLend-->Cash")+(E4:E39="add-->Cash")+(E4:E39="Nagad-->Cash"), D4:D39, 0)) - sum(IF((E4:E39="Cash-->takenLend")+(E4:E39="Cash-->givenLend")+(E4:E39="Cash-->bKash")+(E4:E39="Cash-->SonaliBU"), D4:D39, 0))} -> 3758 | N6: ='March 25'!L7 -> -610 | P6: hRent | Q6: =7000+1500 -> 8500 | R6: =sum(AN4:AN39)+sum(AO4:AO39) -> 8500 | S6: =Q6-R6 -> 0 | U6: =X6+Z6+AB6+AD6+AF6+AH6+AJ6+AL6+AN6+AP6+AR6+AT6 -> 9145 | V6: =Y6+AA6+AC6+AE6+AG6+AI6+AK6+AM6+AO6+AQ6+AS6+AU6 -> 200 | W6: =IF(H6<>"", TEXT(H6, "DD/MM/YY"), "") -> 28/03/25 | Z6: =160+35 -> 195 | AG6: 200 | AH6: 20 | AL6: =140+400+7000 -> 7540 | AR6: =90+100+200+1000 -> 1390
B7: 45741 | D7: 2500 | E7: S_A/C-->bKash | G7: saturday | H7: 45745 | I7: =X7+Z7+AB7+AD7+AF7+AH7+AJ7+AL7+AN7+AP7+AR7+AT7 -> 1000 | J7: =Y7+AA7+AC7+AE7+AG7+AI7+AK7+AM7+AO7+AQ7+AS7+AU7 -> 1400 | L7: givenLend | M7: {=N7 + sum(IF((E4:E39="bKash-->givenLend")+(E4:E39="Cash-->givenLend")+(E4:E39="SonaliBU-->givenLend"), D4:D39, 0)) - sum(IF((E4:E39="givenLend-->bKash")+(E4:E39="givenLend-->Cash")+(E4:E39="givenLend-->SonaliBU")+(E4:E39="givenLend-->Nagad"), D4:D39, 0))} -> 2500 | N7: ='March 25'!L8 -> 1000 | P7: extExp | Q7: 10000 | R7: =sum(AH4:AH39)+sum(AI4:AI39) -> 4984 | S7: =Q7-R7 -> 5016 | U7: =X7+Z7+AB7+AD7+AF7+AH7+AJ7+AL7+AN7+AP7+AR7+AT7 -> 1000 | V7: =Y7+AA7+AC7+AE7+AG7+AI7+AK7+AM7+AO7+AQ7+AS7+AU7 -> 1400 | W7: =IF(H7<>"", TEXT(H7, "DD/MM/YY"), "") -> 29/03/25 | AK7: 1400 | AL7: 1000
B8: 45742 | D8: 1000 | E8: add-->Cash | G8: sunday | H8: 45746 | I8: =X8+Z8+AB8+AD8+AF8+AH8+AJ8+AL8+AN8+AP8+AR8+AT8 -> 0 | J8: =Y8+AA8+AC8+AE8+AG8+AI8+AK8+AM8+AO8+AQ8+AS8+AU8 -> 208 | L8: takenLend | M8: {=N8 + sum(IF((E4:E39="takenLend-->Cash")+(E4:E39="takenLend-->bKash"), D4:D39, 0)) - sum(IF((E4:E39="Cash-->takenLend")+(E4:E39="bKash-->takenLend"), D4:D39, 0))} -> 0 | N8: ='March 25'!L9 -> 0 | P8: internet | Q8: 1200 | R8: =sum(AF4:AF39)+sum(AG4:AG39) -> 1597 | S8: =Q8-R8 -> -397 | U8: =X8+Z8+AB8+AD8+AF8+AH8+AJ8+AL8+AN8+AP8+AR8+AT8 -> 0 | V8: =Y8+AA8+AC8+AE8+AG8+AI8+AK8+AM8+AO8+AQ8+AS8+AU8 -> 208 | W8: =IF(H8<>"", TEXT(H8, "DD/MM/YY"), "") -> 30/03/25 | AG8: 208
B9: 45742 | D9: 1120 | E9: add-->bKash | G9: monday | H9: 45747 | I9: =X9+Z9+AB9+AD9+AF9+AH9+AJ9+AL9+AN9+AP9+AR9+AT9 -> 0 | J9: =Y9+AA9+AC9+AE9+AG9+AI9+AK9+AM9+AO9+AQ9+AS9+AU9 -> 100 | L9: SonaliBU | M9: {=N9 + sum(IF((E4:E39="S_A/C-->SonaliBU")+(E4:E39="givenLend-->SonaliBU")+(E4:E39="Cash-->SonaliBU"), D4:D39, 0)) - sum(IF((E4:E39="SonaliBU-->givenLend"), D4:D39, 0))} -> 5290 | N9: ='March 25'!L10 -> 290 | P9: sav_2.5 | Q9: 2500 | R9: =sum(AP4:AP39)+sum(AQ4:AQ39) -> 2500 | S9: =Q9-R9 -> 0 | U9: =X9+Z9+AB9+AD9+AF9+AH9+AJ9+AL9+AN9+AP9+AR9+AT9 -> 0 | V9: =Y9+AA9+AC9+AE9+AG9+AI9+AK9+AM9+AO9+AQ9+AS9+AU9 -> 100 | W9: =IF(H9<>"", TEXT(H9, "DD/MM/YY"), "") -> 31/03/25 | AI9: 100
B10: 45742 | D10: 5000 | E10: Cash-->SonaliBU | G10: tuesday | H10: 45748 | I10: =X10+Z10+AB10+AD10+AF10+AH10+AJ10+AL10+AN10+AP10+AR10+AT10 -> 8385 | J10: =Y10+AA10+AC10+AE10+AG10+AI10+AK10+AM10+AO10+AQ10+AS10+AU10 -> 0 | L10: EximBank | M10: =N10 -> 507 | N10: ='March 25'!L11 -> 507 | P10: sav_5 | Q10: 0 | S10: =Q10-R10 -> 0 | U10: =X10+Z10+AB10+AD10+AF10+AH10+AJ10+AL10+AN10+AP10+AR10+AT10 -> 8385 | V10: =Y10+AA10+AC10+AE10+AG10+AI10+AK10+AM10+AO10+AQ10+AS10+AU10 -> 0 | W10: =IF(H10<>"", TEXT(H10, "DD/MM/YY"), "") -> 01/04/25 | Z10: 35 | AL10: =5000+3350 -> 8350
B11: 28-03-25 | C11: 15 | D11: 10000 | E11: S_A/C-->Cash | G11: wednesday | H11: 45749 | I11: =X11+Z11+AB11+AD11+AF11+AH11+AJ11+AL11+AN11+AP11+AR11+AT11 -> 0 | J11: =Y11+AA11+AC11+AE11+AG11+AI11+AK11+AM11+AO11+AQ11+AS11+AU11 -> 0 | L11: Nagad | M11: {=N11 + sum(IF((E4:E39="givenLend-->Nagad"), D4:D39, 0)) - sum(IF((E4:E39="Nagad-->Cash"), D4:D39, 0)) - - sum(IF((E4:E39="Nagad-->Cash"), C4:C39, 0))} -> 800 | N11: ='March 25'!L12 | P11: dailyNec | Q11: 1000 | R11: =sum(AD4:AD39)+sum(AE4:AE39) -> 355 | S11: =Q11-R11 -> 645 | U11: =X11+Z11+AB11+AD11+AF11+AH11+AJ11+AL11+AN11+AP11+AR11+AT11 -> 0 | V11: =Y11+AA11+AC11+AE11+AG11+AI11+AK11+AM11+AO11+AQ11+AS11+AU11 -> 0 | W11: =IF(H11<>"", TEXT(H11, "DD/MM/YY"), "") -> 02/04/25
C12: 15 | D12: 3000 | E12: S_A/C-->Cash | G12: thursday | H12: 45750 | I12: =X12+Z12+AB12+AD12+AF12+AH12+AJ12+AL12+AN12+AP12+AR12+AT12 -> 0 | J12: =Y12+AA12+AC12+AE12+AG12+AI12+AK12+AM12+AO12+AQ12+AS12+AU12 -> 0 | N12: ='March 25'!L13 | P12: food | Q12: 800 | R12: =sum(AB4:AB39)+sum(AC4:AC39) -> 2020 | S12: =Q12-R12 -> -1220 | U12: =X12+Z12+AB12+AD12+AF12+AH12+AJ12+AL12+AN12+AP12+AR12+AT12 -> 0 | V12: =Y12+AA12+AC12+AE12+AG12+AI12+AK12+AM12+AO12+AQ12+AS12+AU12 -> 0 | W12: =IF(H12<>"", TEXT(H12, "DD/MM/YY"), "") -> 03/04/25
C13: 15 | D13: 3000 | E13: S_A/C-->Cash | G13: friday | H13: 45751 | I13: =X13+Z13+AB13+AD13+AF13+AH13+AJ13+AL13+AN13+AP13+AR13+AT13 -> 0 | J13: =Y13+AA13+AC13+AE13+AG13+AI13+AK13+AM13+AO13+AQ13+AS13+AU13 -> 0 | P13: travel | Q13: 2000 | R13: =sum(AJ4:AJ39)+sum(AK4:AK39) -> 10420 | S13: =Q13-R13 -> -8420 | U13: =X13+Z13+AB13+AD13+AF13+AH13+AJ13+AL13+AN13+AP13+AR13+AT13 -> 0 | V13: =Y13+AA13+AC13+AE13+AG13+AI13+AK13+AM13+AO13+AQ13+AS13+AU13 -> 0 | W13: =IF(H13<>"", TEXT(H13, "DD/MM/YY"), "") -> 04/04/25
C14: 15 | D14: 10000 | E14: S_A/C-->Cash | G14: saturday | H14: 45752 | I14: =X14+Z14+AB14+AD14+AF14+AH14+AJ14+AL14+AN14+AP14+AR14+AT14 -> 0 | J14: =Y14+AA14+AC14+AE14+AG14+AI14+AK14+AM14+AO14+AQ14+AS14+AU14 -> 1030 | L14: LEND GIVEN TO | N14: =sum(N16:N21) -> 2500 | P14: tea | Q14: 1000 | R14: =sum(Z4:Z39)+sum(AA4:AA39) -> 2252 | S14: =Q14-R14 -> -1252 | U14: =X14+Z14+AB14+AD14+AF14+AH14+AJ14+AL14+AN14+AP14+AR14+AT14 -> 0 | V14: =Y14+AA14+AC14+AE14+AG14+AI14+AK14+AM14+AO14+AQ14+AS14+AU14 -> 1030 | W14: =IF(H14<>"", TEXT(H14, "DD/MM/YY"), "") -> 05/04/25 | AI14: =460+560+5+5 -> 1030
C15: 0 | D15: 2500 | E15: S_A/C-->Cash | G15: sunday | H15: 45753 | I15: =X15+Z15+AB15+AD15+AF15+AH15+AJ15+AL15+AN15+AP15+AR15+AT15 -> 115 | J15: =Y15+AA15+AC15+AE15+AG15+AI15+AK15+AM15+AO15+AQ15+AS15+AU15 -> 0 | L15: Date | M15: Given To | N15: Amount | P15: lendGiven | Q15: 0 | S15: =Q15-R15 -> 0 | U15: =X15+Z15+AB15+AD15+AF15+AH15+AJ15+AL15+AN15+AP15+AR15+AT15 -> 115 | V15: =Y15+AA15+AC15+AE15+AG15+AI15+AK15+AM15+AO15+AQ15+AS15+AU15 -> 0 | W15: =IF(H15<>"", TEXT(H15, "DD/MM/YY"), "") -> 06/04/25 | Z15: 5 | AD15: 110
B16: 45722 | C16: 0 | D16: 1000 | E16: givenLend-->Nagad | G16: monday | H16: 45754 | I16: =X16+Z16+AB16+AD16+AF16+AH16+AJ16+AL16+AN16+AP16+AR16+AT16 -> 150 | J16: =Y16+AA16+AC16+AE16+AG16+AI16+AK16+AM16+AO16+AQ16+AS16+AU16 -> 0 | L16: 45774 | M16: Rajib Vai | N16: =1500+1000 -> 2500 | P16: donation | Q16: 1500 | R16: =sum(AR4:AR39)+sum(AS4:AS39) -> 1460 | S16: =Q16-R16 -> 40 | U16: =X16+Z16+AB16+AD16+AF16+AH16+AJ16+AL16+AN16+AP16+AR16+AT16 -> 150 | V16: =Y16+AA16+AC16+AE16+AG16+AI16+AK16+AM16+AO16+AQ16+AS16+AU16 -> 0 | W16: =IF(H16<>"", TEXT(H16, "DD/MM/YY"), "") -> 07/04/25 | X16: 135 | Z16: 15
B17: 45722 | C17: 0 | D17: 100 | E17: add-->bKash | G17: tuesday | H17: 45755 | I17: =X17+Z17+AB17+AD17+AF17+AH17+AJ17+AL17+AN17+AP17+AR17+AT17 -> 7015 | J17: =Y17+AA17+AC17+AE17+AG17+AI17+AK17+AM17+AO17+AQ17+AS17+AU17 -> 1855 | P17: mess | Q17: 1500 | R17: =sum(X4:X39)+sum(Y4:Y39) -> 1660 | S17: =Q17-R17 -> -160 | U17: =X17+Z17+AB17+AD17+AF17+AH17+AJ17+AL17+AN17+AP17+AR17+AT17 -> 7015 | V17: =Y17+AA17+AC17+AE17+AG17+AI17+AK17+AM17+AO17+AQ17+AS17+AU17 -> 1855 | W17: =IF(H17<>"", TEXT(H17, "DD/MM/YY"), "") -> 08/04/25 | Z17: 15 | AI17: =1850+5 -> 1855 | AN17: 7000
D18: 9000 | E18: add-->S_A/C | G18: wednesday | H18: 45756 | I18: =X18+Z18+AB18+AD18+AF18+AH18+AJ18+AL18+AN18+AP18+AR18+AT18 -> 85 | J18: =Y18+AA18+AC18+AE18+AG18+AI18+AK18+AM18+AO18+AQ18+AS18+AU18 -> 0 | U18: =X18+Z18+AB18+AD18+AF18+AH18+AJ18+AL18+AN18+AP18+AR18+AT18 -> 85 | V18: =Y18+AA18+AC18+AE18+AG18+AI18+AK18+AM18+AO18+AQ18+AS18+AU18 -> 0 | W18: =IF(H18<>"", TEXT(H18, "DD/MM/YY"), "") -> 09/04/25 | X18: 70 | Z18: 15
C19: 15 | D19: 5000 | E19: S_A/C-->Cash | G19: thursday | H19: 45757 | I19: =X19+Z19+AB19+AD19+AF19+AH19+AJ19+AL19+AN19+AP19+AR19+AT19 -> 75 | J19: =Y19+AA19+AC19+AE19+AG19+AI19+AK19+AM19+AO19+AQ19+AS19+AU19 -> 0 | U19: =X19+Z19+AB19+AD19+AF19+AH19+AJ19+AL19+AN19+AP19+AR19+AT19 -> 75 | V19: =Y19+AA19+AC19+AE19+AG19+AI19+AK19+AM19+AO19+AQ19+AS19+AU19 -> 0 | W19: =IF(H19<>"", TEXT(H19, "DD/MM/YY"), "") -> 10/04/25 | Z19: =30+45 -> 75
C20: 15 | D20: 5000 | E20: S_A/C-->Cash | G20: friday | H20: 45758 | I20: =X20+Z20+AB20+AD20+AF20+AH20+AJ20+AL20+AN20+AP20+AR20+AT20 -> 440 | J20: =Y20+AA20+AC20+AE20+AG20+AI20+AK20+AM20+AO20+AQ20+AS20+AU20 -> 0 | U20: =X20+Z20+AB20+AD20+AF20+AH20+AJ20+AL20+AN20+AP20+AR20+AT20 -> 440 | V20: =Y20+AA20+AC20+AE20+AG20+AI20+AK20+AM20+AO20+AQ20+AS20+AU20 -> 0 | W20: =IF(H20<>"", TEXT(H20, "DD/MM/YY"), "") -> 11/04/25 | Z20: =15+30+15 -> 60 | AB20: 20 | AH20: 350 | AR20: 10
D21: 1000 | E21: S_A/C-->bKash | G21: saturday | H21: 45759 | I21: =X21+Z21+AB21+AD21+AF21+AH21+AJ21+AL21+AN21+AP21+AR21+AT21 -> 130 | J21: =Y21+AA21+AC21+AE21+AG21+AI21+AK21+AM21+AO21+AQ21+AS21+AU21 -> 1205 | U21: =X21+Z21+AB21+AD21+AF21+AH21+AJ21+AL21+AN21+AP21+AR21+AT21 -> 130 | V21: =Y21+AA21+AC21+AE21+AG21+AI21+AK21+AM21+AO21+AQ21+AS21+AU21 -> 1205 | W21: =IF(H21<>"", TEXT(H21, "DD/MM/YY"), "") -> 12/04/25 | Z21: =15*4 -> 60 | AB21: 20 | AD21: 50 | AK21: 1205
D22: 200 | E22: Nagad-->Cash | G22: sunday | H22: 45760 | I22: =X22+Z22+AB22+AD22+AF22+AH22+AJ22+AL22+AN22+AP22+AR22+AT22 -> 45 | J22: =Y22+AA22+AC22+AE22+AG22+AI22+AK22+AM22+AO22+AQ22+AS22+AU22 -> 0 | U22: =X22+Z22+AB22+AD22+AF22+AH22+AJ22+AL22+AN22+AP22+AR22+AT22 -> 45 | V22: =Y22+AA22+AC22+AE22+AG22+AI22+AK22+AM22+AO22+AQ22+AS22+AU22 -> 0 | W22: =IF(H22<>"", TEXT(H22, "DD/MM/YY"), "") -> 13/04/25 | Z22: 15 | AB22: 30
D23: 200 | E23: Cash-->bKash | G23: monday | H23: 45761 | I23: =X23+Z23+AB23+AD23+AF23+AH23+AJ23+AL23+AN23+AP23+AR23+AT23 -> 265 | J23: =Y23+AA23+AC23+AE23+AG23+AI23+AK23+AM23+AO23+AQ23+AS23+AU23 -> 0 | L23: LEND TAKEN FROM | N23: =sum(N25:N30) -> 0 | U23: =X23+Z23+AB23+AD23+AF23+AH23+AJ23+AL23+AN23+AP23+AR23+AT23 -> 265 | V23: =Y23+AA23+AC23+AE23+AG23+AI23+AK23+AM23+AO23+AQ23+AS23+AU23 -> 0 | W23: =IF(H23<>"", TEXT(H23, "DD/MM/YY"), "") -> 14/04/25 | Z23: =15+20+5+15 -> 55 | AB23: 20 | AH23: 190
D24: 1720 | E24: S_A/C-->Cash | G24: tuesday | H24: 45762 | I24: =X24+Z24+AB24+AD24+AF24+AH24+AJ24+AL24+AN24+AP24+AR24+AT24 -> 170 | J24: =Y24+AA24+AC24+AE24+AG24+AI24+AK24+AM24+AO24+AQ24+AS24+AU24 -> 0 | L24: Date | M24: Taken From | N24: Amount | U24: =X24+Z24+AB24+AD24+AF24+AH24+AJ24+AL24+AN24+AP24+AR24+AT24 -> 170 | V24: =Y24+AA24+AC24+AE24+AG24+AI24+AK24+AM24+AO24+AQ24+AS24+AU24 -> 0 | W24: =IF(H24<>"", TEXT(H24, "DD/MM/YY"), "") -> 15/04/25 | X24: 130 | Z24: 40
D25: 1399 | E25: S_A/C-->Cash | G25: wednesday | H25: 45763 | I25: =X25+Z25+AB25+AD25+AF25+AH25+AJ25+AL25+AN25+AP25+AR25+AT25 -> 0 | J25: =Y25+AA25+AC25+AE25+AG25+AI25+AK25+AM25+AO25+AQ25+AS25+AU25 -> 100 | U25: =X25+Z25+AB25+AD25+AF25+AH25+AJ25+AL25+AN25+AP25+AR25+AT25 -> 0 | V25: =Y25+AA25+AC25+AE25+AG25+AI25+AK25+AM25+AO25+AQ25+AS25+AU25 -> 100 | W25: =IF(H25<>"", TEXT(H25, "DD/MM/YY"), "") -> 16/04/25 | AG25: 100
B26: 45742 | D26: 1500 | E26: S_A/C-->bKash | G26: thursday | H26: 45764 | I26: =X26+Z26+AB26+AD26+AF26+AH26+AJ26+AL26+AN26+AP26+AR26+AT26 -> 2540 | J26: =Y26+AA26+AC26+AE26+AG26+AI26+AK26+AM26+AO26+AQ26+AS26+AU26 -> 0 | U26: =X26+Z26+AB26+AD26+AF26+AH26+AJ26+AL26+AN26+AP26+AR26+AT26 -> 2540 | V26: =Y26+AA26+AC26+AE26+AG26+AI26+AK26+AM26+AO26+AQ26+AS26+AU26 -> 0 | W26: =IF(H26<>"", TEXT(H26, "DD/MM/YY"), "") -> 17/04/25 | Z26: =15+290 -> 305 | AB26: =210+70+60 -> 340 | AD26: =125+50 -> 175 | AJ26: 1720
B27: 45742 | D27: 1500 | E27: bKash-->givenLend | G27: friday | H27: 45765 | I27: =X27+Z27+AB27+AD27+AF27+AH27+AJ27+AL27+AN27+AP27+AR27+AT27 -> 960 | J27: =Y27+AA27+AC27+AE27+AG27+AI27+AK27+AM27+AO27+AQ27+AS27+AU27 -> 0 | U27: =X27+Z27+AB27+AD27+AF27+AH27+AJ27+AL27+AN27+AP27+AR27+AT27 -> 960 | V27: =Y27+AA27+AC27+AE27+AG27+AI27+AK27+AM27+AO27+AQ27+AS27+AU27 -> 0 | W27: =IF(H27<>"", TEXT(H27, "DD/MM/YY"), "") -> 18/04/25 | Z27: =20+10 -> 30 | AB27: =220+70+40+500 -> 830 | AJ27: =20+30+10+40 -> 100
B28: 45743 | D28: 1000 | E28: S_A/C-->bKash | G28: saturday | H28: 45766 | I28: =X28+Z28+AB28+AD28+AF28+AH28+AJ28+AL28+AN28+AP28+AR28+AT28 -> 1090 | J28: =Y28+AA28+AC28+AE28+AG28+AI28+AK28+AM28+AO28+AQ28+AS28+AU28 -> 0 | U28: =X28+Z28+AB28+AD28+AF28+AH28+AJ28+AL28+AN28+AP28+AR28+AT28 -> 1090 | V28: =Y28+AA28+AC28+AE28+AG28+AI28+AK28+AM28+AO28+AQ28+AS28+AU28 -> 0 | W28: =IF(H28<>"", TEXT(H28, "DD/MM/YY"), "") -> 19/04/25 | Z28: =300+10 -> 310 | AB28: =25+50+230+20 -> 325 | AH28: 20 | AJ28: =20+20+170+65+20+100+40 -> 435
B29: 45743 | D29: 1000 | E29: bKash-->givenLend | G29: sunday | H29: 45767 | I29: =X29+Z29+AB29+AD29+AF29+AH29+AJ29+AL29+AN29+AP29+AR29+AT29 -> 5960 | J29: =Y29+AA29+AC29+AE29+AG29+AI29+AK29+AM29+AO29+AQ29+AS29+AU29 -> 0 | U29: =X29+Z29+AB29+AD29+AF29+AH29+AJ29+AL29+AN29+AP29+AR29+AT29 -> 5960 | V29: =Y29+AA29+AC29+AE29+AG29+AI29+AK29+AM29+AO29+AQ29+AS29+AU29 -> 0 | W29: =IF(H29<>"", TEXT(H29, "DD/MM/YY"), "") -> 20/04/25 | Z29: =195+300+25+90+45+35+90 -> 780 | AB29: =50 -> 50 | AD29: =10 -> 10 | AJ29: =1970+430+1350+250+60+60+1000 -> 5120
E30: None | G30: monday | H30: 45768 | I30: =X30+Z30+AB30+AD30+AF30+AH30+AJ30+AL30+AN30+AP30+AR30+AT30 -> 0 | J30: =Y30+AA30+AC30+AE30+AG30+AI30+AK30+AM30+AO30+AQ30+AS30+AU30 -> 0 | U30: =X30+Z30+AB30+AD30+AF30+AH30+AJ30+AL30+AN30+AP30+AR30+AT30 -> 0 | V30: =Y30+AA30+AC30+AE30+AG30+AI30+AK30+AM30+AO30+AQ30+AS30+AU30 -> 0 | W30: =IF(H30<>"", TEXT(H30, "DD/MM/YY"), "") -> 21/04/25
E31: None | G31: tuesday | H31: 45769 | I31: =X31+Z31+AB31+AD31+AF31+AH31+AJ31+AL31+AN31+AP31+AR31+AT31 -> 0 | J31: =Y31+AA31+AC31+AE31+AG31+AI31+AK31+AM31+AO31+AQ31+AS31+AU31 -> 0 | U31: =X31+Z31+AB31+AD31+AF31+AH31+AJ31+AL31+AN31+AP31+AR31+AT31 -> 0 | V31: =Y31+AA31+AC31+AE31+AG31+AI31+AK31+AM31+AO31+AQ31+AS31+AU31 -> 0 | W31: =IF(H31<>"", TEXT(H31, "DD/MM/YY"), "") -> 22/04/25
E32: None | G32: wednesday | H32: 45770 | I32: =X32+Z32+AB32+AD32+AF32+AH32+AJ32+AL32+AN32+AP32+AR32+AT32 -> 1345 | J32: =Y32+AA32+AC32+AE32+AG32+AI32+AK32+AM32+AO32+AQ32+AS32+AU32 -> 150 | U32: =X32+Z32+AB32+AD32+AF32+AH32+AJ32+AL32+AN32+AP32+AR32+AT32 -> 1345 | V32: =Y32+AA32+AC32+AE32+AG32+AI32+AK32+AM32+AO32+AQ32+AS32+AU32 -> 150 | W32: =IF(H32<>"", TEXT(H32, "DD/MM/YY"), "") -> 23/04/25 | X32: =1325 -> 1325 | AG32: 150 | AH32: 20
E33: None | G33: thursday | H33: 45771 | I33: =X33+Z33+AB33+AD33+AF33+AH33+AJ33+AL33+AN33+AP33+AR33+AT33 -> 30 | J33: =Y33+AA33+AC33+AE33+AG33+AI33+AK33+AM33+AO33+AQ33+AS33+AU33 -> 200 | U33: =X33+Z33+AB33+AD33+AF33+AH33+AJ33+AL33+AN33+AP33+AR33+AT33 -> 30 | V33: =Y33+AA33+AC33+AE33+AG33+AI33+AK33+AM33+AO33+AQ33+AS33+AU33 -> 200 | W33: =IF(H33<>"", TEXT(H33, "DD/MM/YY"), "") -> 24/04/25 | Z33: 30 | AG33: 200
E34: None | G34: friday | H34: 45772 | I34: =X34+Z34+AB34+AD34+AF34+AH34+AJ34+AL34+AN34+AP34+AR34+AT34 -> 57 | J34: =Y34+AA34+AC34+AE34+AG34+AI34+AK34+AM34+AO34+AQ34+AS34+AU34 -> 689 | U34: =X34+Z34+AB34+AD34+AF34+AH34+AJ34+AL34+AN34+AP34+AR34+AT34 -> 57 | V34: =Y34+AA34+AC34+AE34+AG34+AI34+AK34+AM34+AO34+AQ34+AS34+AU34 -> 689 | W34: =IF(H34<>"", TEXT(H34, "DD/MM/YY"), "") -> 25/04/25 | Z34: =22+15 -> 37 | AB34: 20 | AG34: 689
E35: None | G35: saturday | H35: 45773 | I35: =X35+Z35+AB35+AD35+AF35+AH35+AJ35+AL35+AN35+AP35+AR35+AT35 -> 1494 | J35: =Y35+AA35+AC35+AE35+AG35+AI35+AK35+AM35+AO35+AQ35+AS35+AU35 -> 50 | U35: =X35+Z35+AB35+AD35+AF35+AH35+AJ35+AL35+AN35+AP35+AR35+AT35 -> 1494 | V35: =Y35+AA35+AC35+AE35+AG35+AI35+AK35+AM35+AO35+AQ35+AS35+AU35 -> 50 | W35: =IF(H35<>"", TEXT(H35, "DD/MM/YY"), "") -> 26/04/25 | Z35: =30+15+30 -> 75 | AB35: 20 | AG35: 50 | AH35: 1399
E36: None | I36: =X36+Z36+AB36+AD36+AF36+AH36+AJ36+AL36+AN36+AP36+AR36+AT36 -> 55 | J36: =Y36+AA36+AC36+AE36+AG36+AI36+AK36+AM36+AO36+AQ36+AS36+AU36 -> 0 | U36: =X36+Z36+AB36+AD36+AF36+AH36+AJ36+AL36+AN36+AP36+AR36+AT36 -> 55 | V36: =Y36+AA36+AC36+AE36+AG36+AI36+AK36+AM36+AO36+AQ36+AS36+AU36 -> 0 | W36: 45774 | Z36: =30+25 -> 55
E37: None | I37: =X37+Z37+AB37+AD37+AF37+AH37+AJ37+AL37+AN37+AP37+AR37+AT37 -> 0 | J37: =Y37+AA37+AC37+AE37+AG37+AI37+AK37+AM37+AO37+AQ37+AS37+AU37 -> 0 | U37: =X37+Z37+AB37+AD37+AF37+AH37+AJ37+AL37+AN37+AP37+AR37+AT37 -> 0 | V37: =Y37+AA37+AC37+AE37+AG37+AI37+AK37+AM37+AO37+AQ37+AS37+AU37 -> 0 | W37: =IF(H37<>"", TEXT(H37, "DD/MM/YY"), "")
E38: None | I38: =X38+Z38+AB38+AD38+AF38+AH38+AJ38+AL38+AN38+AP38+AR38+AT38 -> 0 | J38: =Y38+AA38+AC38+AE38+AG38+AI38+AK38+AM38+AO38+AQ38+AS38+AU38 -> 0 | U38: =X38+Z38+AB38+AD38+AF38+AH38+AJ38+AL38+AN38+AP38+AR38+AT38 -> 0 | V38: =Y38+AA38+AC38+AE38+AG38+AI38+AK38+AM38+AO38+AQ38+AS38+AU38 -> 0 | W38: =IF(H38<>"", TEXT(H38, "DD/MM/YY"), "")
E39: None | I39: =X39+Z39+AB39+AD39+AF39+AH39+AJ39+AL39+AN39+AP39+AR39+AT39 -> 0 | J39: =Y39+AA39+AC39+AE39+AG39+AI39+AK39+AM39+AO39+AQ39+AS39+AU39 -> 0 | U39: =X39+Z39+AB39+AD39+AF39+AH39+AJ39+AL39+AN39+AP39+AR39+AT39 -> 0 | V39: =Y39+AA39+AC39+AE39+AG39+AI39+AK39+AM39+AO39+AQ39+AS39+AU39 -> 0 | W39: =IF(H39<>"", TEXT(H39, "DD/MM/YY"), "")
G49: 45805 | H49: =190+110 -> 300
G50: 45806 | H50: =100+50 -> 150 | I50: need to give santo | K50: 140
...

Sheet data
A1: Category | B1: Subcategory | C1: UniqueCategories | D1: PaymentMethod | E1: Account | F1: Formula | G1: SavingsAcc
A2: RentAndPaybill | B2: HouseRent | C2: {=UNIQUE(A2:A1006)} -> RentAndPaybill | D2: Cash | E2: Cash | G2: EximBank_2.5 | K2: FLATTEN(ARRAYFORMULA(IF(D2:D7<>TRANSPOSE(D2:D7),D2:D7&" > "&TRANSPOSE(D2:D7),"")))
A3: RentAndPaybill | B3: ElectricBill_Dhk | C3: Bazar | D3: SCB | E3: SCB | G3: CityBank_10
A4: RentAndPaybill | B4: ElectricBill_Swk | C4: HouseholdAccessories | D4: SBL | E4: SBL | G4: BracBank_10
A5: RentAndPaybill | B5: GassBill | C5: MobileInternet | D5: EXIM | E5: EXIM | G5: SBL_root
A6: RentAndPaybill | B6: WifiBill | C6: ExtraExpenses | D6: bKash | E6: bKash | G6: Exim_root
A7: RentAndPaybill | B7: ServiceBill | C7: Savings | D7: Nagad | E7: Nagad
A8: Bazar | B8: DailyBazar | C8: Donation | D8: City | E8: LendTaken
A9: Bazar | B9: Fruits | C9: Pay | E9: LendGiven
A10: Bazar | B10: AdvGiven | E10: City
A11: Bazar | B11: Others | E11: Add
A12: HouseholdAccessories | B12: HouseholdAccessories | E12: Pay
A13: HouseholdAccessories | B13: DailyAccessories
A14: HouseholdAccessories | B14: Medicine
A15: MobileInternet | B15: ForMine
A16: MobileInternet | B16: ForOthers
A17: ExtraExpenses | B17: Tea
A18: ExtraExpenses | B18: Travel
A19: ExtraExpenses | B19: AiSubs
A20: ExtraExpenses | B20: BooksOrCourses
A21: ExtraExpenses | B21: ExtraExpenses
A22: Savings | B22: EximBank_2.5
A23: Savings | B23: CityBank_10
A24: Savings | B24: BracBank_10
... A31: Pay | B31: BracService

Sheet June 25
B2: T r a n s a c t i o n & P a y | H2: DAY | I2: Date | L2: FINANCIAL STATUS | N2: =M4+M5+M6+M8+M9 -> 420 | P2: Date | Q2: Category | R2: Subcategory | S2: Payment Method | T2: Amount | U2: Remarks
B3: Date | C3: Cost | D3: Amount | E3: FROM | F3: TO | J3: Cost | L3: Type | M3: Current Status | N3: Start with | P3: 45807 | Q3: Bazar | R3: DailyBazar | S3: Cash | T3: =360+20+330+30 -> 740
B4: 45804 | D4: 49500 | E4: Add | F4: SCB | H4: =TEXT(I4, "dddd") -> Monday | I4: 45803 | J4: {=sum(IF(($P$3:$P$100=I4), $T$3:$T$100, 0))} -> 0 | L4: {=INDIRECT("Account")} -> Cash | M4: {=N4 - sum(IF(($E$4:$E$49=L4), $D$4:$D$39 + $C$4:$C$39, 0)) + sum(IF(($F$4:$F$49=L4), $D$4:$D$39, 0)) - sum(IF(($S$3:$S$100=L4), $T$3:$T$100, 0))} -> 35 | N4: 0 | P4: 45807 | Q4: Bazar | R4: Fruits | S4: Cash | T4: 400
B5: 45804 | D5: 3333 | E5: Add | F5: SCB | H5: =TEXT(I5, "dddd") -> Tuesday | I5: 45804 | J5: {=sum(IF(($P$3:$P$100=I5), $T$3:$T$100, 0))} -> 0 | L5: SCB | M5: {=N5 - sum(IF(($E$4:$E$49=L5), $D$4:$D$39 + $C$4:$C$39, 0)) + sum(IF(($F$4:$F$49=L5), $D$4:$D$39, 0)) - sum(IF(($S$3:$S$100=L5), $T$3:$T$100, 0))} -> 8 | N5: 0 | P5: 45808 | Q5: ExtraExpenses | R5: ExtraExpenses | S5: Cash | T5: 103000
B6: 45804 | D6: 150000 | E6: Add | F6: SCB | H6: =TEXT(I6, "dddd") -> Wednesday | I6: 45805 | J6: {=sum(IF(($P$3:$P$100=I6), $T$3:$T$100, 0))} -> 0 | L6: SBL | M6: {=N6 - sum(IF(($E$4:$E$49=L6), $D$4:$D$39 + $C$4:$C$39, 0)) + sum(IF(($F$4:$F$49=L6), $D$4:$D$39, 0)) - sum(IF(($S$3:$S$100=L6), $T$3:$T$100, 0))} -> 249 | N6: 10264 | P6: 45808 | Q6: HouseholdAccessories | R6: DailyAccessories | S6: Cash | T6: 40 | U6: shampoo
B7: 45805 | C7: 15 | D7: 10000 | E7: SCB | F7: Cash | H7: =TEXT(I7, "dddd") -> Thursday | I7: 45806 | J7: {=sum(IF(($P$3:$P$100=I7), $T$3:$T$100, 0))} -> 0 | L7: EXIM | M7: {=N7 - sum(IF(($E$4:$E$49=L7), $D$4:$D$39 + $C$4:$C$39, 0)) + sum(IF(($F$4:$F$49=L7), $D$4:$D$39, 0)) - sum(IF(($S$3:$S$100=L7), $T$3:$T$100, 0))} -> 2500 | P7: 45808 | Q7: Bazar | R7: Others | S7: Cash | T7: 80 | U7: ice-cream
B8: 45808 | D8: 1000 | E8: SCB | F8: bKash | H8: =TEXT(I8, "dddd") -> Friday | I8: 45807 | J8: {=sum(IF(($P$3:$P$100=I8), $T$3:$T$100, 0))} -> 1140 | L8: bKash | M8: {=N8 - sum(IF(($E$4:$E$49=L8), $D$4:$D$39 + $C$4:$C$39, 0)) + sum(IF(($F$4:$F$49=L8), $D$4:$D$39, 0)) - sum(IF(($S$3:$S$100=L8), $T$3:$T$100, 0))} -> 11 | N8: 431 | P8: 45808 | Q8: ExtraExpenses | R8: Travel | S8: Cash | T8: =10+20+300 -> 330
B9: 45808 | D9: 103000 | E9: SCB | F9: Cash | H9: =TEXT(I9, "dddd") -> Saturday | I9: 45808 | J9: {=sum(IF(($P$3:$P$100=I9), $T$3:$T$100, 0))} -> 104274 | L9: Nagad | M9: {=N9 - sum(IF(($E$4:$E$49=L9), $D$4:$D$39 + $C$4:$C$39, 0)) + sum(IF(($F$4:$F$49=L9), $D$4:$D$39, 0)) - sum(IF(($S$3:$S$100=L9), $T$3:$T$100, 0))} -> 117 | N9: 117 | P9: 45808 | Q9: ExtraExpenses | R9: Tea | S9: Cash | T9: =15+75+45 -> 135
B10: 45808 | D10: 1750 | E10: SCB | F10: Cash | H10: =TEXT(I10, "dddd") -> Sunday | I10: 45809 | J10: {=sum(IF(($P$3:$P$100=I10), $T$3:$T$100, 0))} -> 6000 | L10: LendTaken | M10: {=N10 - sum(IF(($E$4:$E$49=L10), $D$4:$D$39 + $C$4:$C$39, 0)) + sum(IF(($F$4:$F$49=L10), $D$4:$D$39, 0)) - sum(IF(($S$3:$S$100=L10), $T$3:$T$100, 0))} -> 150000 | N10: 150000 | P10: 45809 | Q10: ExtraExpenses | R10: ExtraExpenses | S10: Cash | T10: 5500 | U10: fridge
B11: 45810 | C11: 15 | D11: 20000 | E11: SCB | F11: Cash | H11: =TEXT(I11, "dddd") -> Monday | I11: 45810 | J11: {=sum(IF(($P$3:$P$100=I11), $T$3:$T$100, 0))} -> 800 | L11: LendGiven | M11: {=N11 - sum(IF(($E$4:$E$49=L11), $D$4:$D$39 + $C$4:$C$39, 0)) + sum(IF(($F$4:$F$49=L11), $D$4:$D$39, 0)) - sum(IF(($S$3:$S$100=L11), $T$3:$T$100, 0))} -> 5500 | N11: 2500 | P11: 45809 | Q11: Bazar | R11: AdvGiven | S11: Cash | T11: 500 | U11: ammu
B12: 45810 | D12: 8000 | E12: SCB | F12: Cash | H12: =TEXT(I12, "dddd") -> Tuesday | I12: 45811 | J12: {=sum(IF(($P$3:$P$100=I12), $T$3:$T$100, 0))} -> 8020 | L12: City | P12: 45810 | Q12: Bazar | R12: AdvGiven | S12: Cash | T12: 500 | U12: ammu
B13: 45811 | C13: 15 | D13: 20000 | E13: SCB | F13: Cash | H13: =TEXT(I13, "dddd") -> Wednesday | I13: 45812 | J13: {=sum(IF(($P$3:$P$100=I13), $T$3:$T$100, 0))} -> 49918 | P13: 45810 | Q13: Donation | R13: Donation | S13: Cash | T13: 300
B14: 45812 | C14: 15 | D14: 20000 | E14: SCB | F14: Cash | H14: =TEXT(I14, "dddd") -> Thursday | I14: 45813 | J14: {=sum(IF(($P$3:$P$100=I14), $T$3:$T$100, 0))} -> 4720 | P14: 45811 | Q14: ExtraExpenses | R14: Tea | S14: Cash | T14: 20
B15: 45812 | D15: 1000 | E15: SCB | F15: bKash | H15: =TEXT(I15, "dddd") -> Friday | I15: 45814 | J15: {=sum(IF(($P$3:$P$100=I15), $T$3:$T$100, 0))} -> 2437 | L15: LEND GIVEN TO | N15: =sum(N17:N22) -> 0 | P15: 45812 | Q15: HouseholdAccessories | R15: HouseholdAccessories | S15: Cash | T15: 2000 | U15: ammu
B16: 45816 | D16: 1000 | E16: SCB | F16: bKash | H16: =TEXT(I16, "dddd") -> Saturday | I16: 45815 | J16: {=sum(IF(($P$3:$P$100=I16), $T$3:$T$100, 0))} -> 0 | L16: Date | M16: Given To | N16: Amount | P16: 45812 | Q16: ExtraExpenses | R16: ExtraExpenses | S16: Cash | T16: 5000 | U16: fan
B17: 45818 | C17: 15 | D17: 10000 | E17: SCB | F17: Cash | H17: =TEXT(I17, "dddd") -> Sunday | I17: 45816 | J17: {=sum(IF(($P$3:$P$100=I17), $T$3:$T$100, 0))} -> 680 | P17: 45812 | Q17: ExtraExpenses | R17: ExtraExpenses | S17: bKash | T17: 580 | U17: fan
B18: 45818 | C18: 15 | D18: 10000 | E18: SBL | F18: Cash | H18: =TEXT(I18, "dddd") -> Monday | I18: 45817 | J18: {=sum(IF(($P$3:$P$100=I18), $T$3:$T$100, 0))} -> 3000 | P18: 45812 | Q18: ExtraExpenses | R18: ExtraExpenses | S18: Cash | T18: 250 | U18: sim-teletalk
B19: 45814 | D19: 3000 | E19: SCB | F19: bKash | H19: =TEXT(I19, "dddd") -> Tuesday | I19: 45818 | J19: {=sum(IF(($P$3:$P$100=I19), $T$3:$T$100, 0))} -> 2140 | P19: 45812 | Q19: ExtraExpenses | R19: ExtraExpenses | S19: Cash | T19: 3910 | U19: gas stove
B20: 45819 | D20: 2500 | E20: SCB | F20: EXIM | H20: =TEXT(I20, "dddd") -> Wednesday | I20: 45819 | J20: {=sum(IF(($P$3:$P$100=I20), $T$4:$T$100, 0))} -> 487 | P20: 45812 | Q20: ExtraExpenses | R20: Travel | S20: Cash | T20: =10+10+30+30+1600 -> 1680 | U20: home-shifting
B21: 45814 | D21: 3000 | E21: bKash | F21: LendGiven | H21: =TEXT(I21, "dddd") -> Thursday | I21: 45820 | J21: {=sum(IF(($P$3:$P$100=I21), $T$4:$T$100, 0))} -> 140 | P21: 45812 | Q21: ExtraExpenses | R21: ExtraExpenses | S21: Cash | T21: 35000 | U21: fridge
B22: 45821 | D22: 500 | E22: SCB | F22: bKash | H22: =TEXT(I22, "dddd") -> Friday | I22: 45821 | J22: {=sum(IF(($P$3:$P$100=I22), $T$4:$T$100, 0))} -> 1510 | P22: 45812 | Q22: HouseholdAccessories | R22: HouseholdAccessories | S22: Cash | T22: =20+200+830 -> 1050 | U22: light, boti
B23: 45829 | D23: 1000 | E23: SCB | F23: bKash | H23: =TEXT(I23, "dddd") -> Saturday | I23: 45822 | J23: {=sum(IF(($P$3:$P$100=I23), $T$4:$T$100, 0))} -> 735 | P23: 45812 | Q23: Bazar | R23: DailyBazar | S23: Cash | T23: =155+90+80+40 -> 365
H24: =TEXT(I24, "dddd") -> Sunday | I24: 45823 | J24: {=sum(IF(($P$3:$P$100=I24), $T$4:$T$100, 0))} -> 130 | L24: LEND TAKEN FROM | N24: =sum(N26:N31) -> 0 | P24: 45812 | Q24: Bazar | R24: Others | S24: Cash | T24: =25+10 -> 35
H25: =TEXT(I25, "dddd") -> Monday | I25: 45824 | J25: {=sum(IF(($P$3:$P$100=I25), $T$4:$T$100, 0))} -> 600 | L25: Date | M25: Taken From | N25: Amount | P25: 45813 | Q25: Bazar | R25: DailyBazar | S25: Cash | T25: =350+400+2000+20+500 -> 3270
H26: =TEXT(I26, "dddd") -> Tuesday | I26: 45825 | J26: {=sum(IF(($P$3:$P$100=I26), $T$4:$T$100, 0))} -> 20 | P26: 45813 | Q26: HouseholdAccessories | R26: DailyAccessories | S26: Cash | T26: 130 | U26: vim
H27: =TEXT(I27, "dddd") -> Wednesday | I27: 45826 | J27: {=sum(IF(($P$3:$P$100=I27), $T$4:$T$100, 0))} -> 400 | P27: 45813 | Q27: HouseholdAccessories | R27: HouseholdAccessories | S27: Cash | T27: =100+70 -> 170 | U27: rosi, electronics
H28: =TEXT(I28, "dddd") -> Thursday | I28: 45827 | J28: {=sum(IF(($P$3:$P$100=I28), $T$4:$T$100, 0))} -> 250 | P28: 45813 | Q28: Bazar | R28: Others | S28: Cash | T28: =200+200+50 -> 450 | U28: ice-cream, biskit, nasta
H29: =TEXT(I29, "dddd") -> Friday | I29: 45828 | J29: {=sum(IF(($P$3:$P$100=I29), $T$4:$T$100, 0))} -> 20 | P29: 45813 | Q29: Bazar | R29: Fruits | S29: Cash | T29: 200
H30: =TEXT(I30, "dddd") -> Saturday | I30: 45829 | J30: {=sum(IF(($P$3:$P$100=I30), $T$4:$T$100, 0))} -> 600 | P30: 45811 | Q30: RentAndPaybill | R30: HouseRent | S30: Cash | T30: 8000 | U30: prev
H31: =TEXT(I31, "dddd") -> Sunday | I31: 45830 | J31: {=sum(IF(($P$3:$P$100=I31), $T$4:$T$100, 0))} -> 410 | P31: 45814 | Q31: Donation | R31: Donation | S31: Cash | T31: 965 | U31: can't find source
H32: =TEXT(I32, "dddd") -> Monday | I32: 45831 | J32: {=sum(IF(($P$3:$P$100=I32), $T$4:$T$100, 0))} -> 125 | P32: 45808 | Q32: RentAndPaybill | R32: ElectricBill_Swk | S32: bKash | T32: 491
H33: =TEXT(I33, "dddd") -> Tuesday | I33: 45832 | J33: {=sum(IF(($P$3:$P$100=I33), $T$4:$T$100, 0))} -> 1201 | N33: =sum(N35:N40) -> 0 | P33: 45808 | Q33: MobileInternet | R33: ForMine | S33: bKash | T33: 148
H34: =TEXT(I34, "dddd") -> Wednesday | I34: 45833 | J34: {=sum(IF(($P$3:$P$100=I34), $T$4:$T$100, 0))} -> 100 | P34: 45808 | Q34: MobileInternet | R34: ForMine | S34: bKash | T34: 50
H35: =TEXT(I35, "dddd") -> Thursday | I35: 45834 | J35: {=sum(IF(($P$3:$P$100=I35), $T$4:$T$100, 0))} -> 0 | P35: 45812 | Q35: MobileInternet | R35: ForMine | S35: bKash | T35: 48
P36: 45813 | Q36: RentAndPaybill | R36: ElectricBill_Dhk | S36: bKash | T36: 500
P37: 45814 | Q37: Bazar | R37: DailyBazar | S37: Cash | T37: =250+190+275+40+40+20+360 -> 1175
P38: 45814 | Q38: Donation | R38: Donation | S38: Cash | T38: =20+20+15 -> 55
P39: 45816 | Q39: Donation | R39: Donation | S39: bKash | T39: 500
P40: 45816 | Q40: ExtraExpenses | R40: ExtraExpenses | S40: Cash | T40: 180
P41: 45817 | Q41: Bazar | R41: AdvGiven | S41: Cash | T41: 3000
...

Sheet July 25
B2: T r a n s a c t i o n & P a y | H2: DAY | I2: Date | J2: =sum(J4:J39) -> 39094 | L2: FINANCIAL STATUS | N2: =M4+M5+M8+M9 -> 60838 | P2: Date | Q2: Category | R2: Subcategory | S2: Payment Method | T2: Amount | U2: Remarks
B3: Date | C3: Cost | D3: Amount | E3: FROM | F3: TO | J3: Cost | L3: Type | M3: Current Status | N3: Start with | P3: 45834 | Q3: HouseholdAccessories | R3: HouseholdAccessories | S3: Cash | T3: =320+110 -> 430 | U3: mask+odofresh
B4: 45834 | D4: 39500 | E4: Add | F4: SCB | H4: =TEXT(I4, "dddd") -> Thursday | I4: 45834 | J4: {=sum(IF(($P$3:$P$100=I4), $T$3:$T$100, 0))} -> 1130 | L4: {=INDIRECT("Account")} -> Cash | M4: {=N4 - sum(IF(($E$4:$E$49=L4), $D$4:$D$39 + $C$4:$C$39, 0)) + sum(IF(($F$4:$F$49=L4), $D$4:$D$39, 0)) - sum(IF(($S$3:$S$100=L4), $T$3:$T$100, 0))} -> 3725 | N4: 0 | P4: 45835 | Q4: Bazar | R4: DailyBazar | S4: Cash | T4: 30
B5: 45834 | C5: 0 | D5: 30000 | E5: SCB | F5: Cash | H5: =TEXT(I5, "dddd") -> Friday | I5: 45835 | J5: {=sum(IF(($P$3:$P$100=I5), $T$3:$T$100, 0))} -> 40 | L5: SCB | M5: {=N5 - sum(IF(($E$4:$E$49=L5), $D$4:$D$39 + $C$4:$C$39, 0)) + sum(IF(($F$4:$F$49=L5), $D$4:$D$39, 0)) - sum(IF(($S$3:$S$100=L5), $T$3:$T$100, 0))} -> 57034 | N5: =31 -> 31 | P5: 45836 | Q5: ExtraExpenses | R5: Travel | S5: Cash | T5: =80+65 -> 145
B6: 45838 | D6: 53333 | E6: Add | F6: SCB | H6: =TEXT(I6, "dddd") -> Saturday | I6: 45836 | J6: {=sum(IF(($P$3:$P$100=I6), $T$3:$T$100, 0))} -> 9765 | L6: SBL | M6: {=N6 - sum(IF(($E$4:$E$49=L6), $D$4:$D$39 + $C$4:$C$39, 0)) + sum(IF(($F$4:$F$49=L6), $D$4:$D$39, 0)) - sum(IF(($S$3:$S$100=L6), $T$3:$T$100, 0))} -> 30191 | N6: 191 | P6: 45836 | Q6: ExtraExpenses | R6: ExtraExpenses | S6: Cash | T6: =3500+30 -> 3530 | U6: fan
B7: 45838 | D7: 30000 | E7: Add | F7: SBL | H7: =TEXT(I7, "dddd") -> Sunday | I7: 45837 | J7: {=sum(IF(($P$3:$P$100=I7), $T$3:$T$100, 0))} -> 1230 | L7: EXIM | M7: {=N7 - sum(IF(($E$4:$E$49=L7), $D$4:$D$39 + $C$4:$C$39, 0)) + sum(IF(($F$4:$F$49=L7), $D$4:$D$39, 0)) - sum(IF(($S$3:$S$100=L7), $T$3:$T$100, 0))} -> 285 | N7: 285 | P7: 45836 | Q7: Bazar | R7: DailyBazar | S7: Cash | T7: 90
B8: 45838 | D8: 800 | E8: SCB | F8: Nagad | H8: =TEXT(I8, "dddd") -> Monday | I8: 45838 | J8: {=sum(IF(($P$3:$P$100=I8), $T$3:$T$100, 0))} -> 385 | L8: bKash | M8: {=N8 - sum(IF(($E$4:$E$49=L8), $D$4:$D$39 + $C$4:$C$39, 0)) + sum(IF(($F$4:$F$49=L8), $D$4:$D$39, 0)) - sum(IF(($S$3:$S$100=L8), $T$3:$T$100, 0))} -> 77 | N8: 11 | P8: 45834 | Q8: ExtraExpenses | R8: Travel | S8: Cash | T8: 700 | U8: abbu
B9: 45846 | D9: 1000 | E9: SCB | F9: bKash | H9: =TEXT(I9, "dddd") -> Tuesday | I9: 45839 | J9: {=sum(IF(($P$3:$P$100=I9), $T$3:$T$100, 0))} -> 905 | L9: Nagad | M9: {=N9 - sum(IF(($E$4:$E$49=L9), $D$4:$D$39 + $C$4:$C$39, 0)) + sum(IF(($F$4:$F$49=L9), $D$4:$D$39, 0)) - sum(IF(($S$3:$S$100=L9), $T$3:$T$100, 0))} -> 2 | N9: 87 | P9: 45837 | Q9: Bazar | R9: DailyBazar | S9: Cash | T9: =660+20+50 -> 730 | U9: murgi
B10: 45850 | C10: 15 | D10: 3000 | E10: SCB | F10: Cash | H10: =TEXT(I10, "dddd") -> Wednesday | I10: 45840 | J10: {=sum(IF(($P$3:$P$100=I10), $T$3:$T$100, 0))} -> 200 | L10: LendTaken | M10: 140000 | N10: 150000 | P10: 45837 | Q10: Bazar | R10: Fruits | S10: Cash | T10: 300 | U10: mango
B11: 45851 | D11: 7000 | E11: Add | F11: SCB | H11: =TEXT(I11, "dddd") -> Thursday | I11: 45841 | J11: {=sum(IF(($P$3:$P$100=I11), $T$3:$T$100, 0))} -> 450 | L11: LendGiven | M11: {=N11 - sum(IF(($E$4:$E$49=L11), $D$4:$D$39 + $C$4:$C$39, 0)) + sum(IF(($F$4:$F$49=L11), $D$4:$D$39, 0)) - sum(IF(($S$3:$S$100=L11), $T$3:$T$100, 0))} -> 5500 | N11: =2500+3000 -> 5500 | P11: 45837 | Q11: Bazar | R11: Others | S11: Cash | T11: 50
B12: 45862 | C12: 15 | D12: 5000 | E12: SCB | F12: Cash | H12: =TEXT(I12, "dddd") -> Friday | I12: 45842 | J12: {=sum(IF(($P$3:$P$100=I12), $T$3:$T$100, 0))} -> 0 | L12: City | P12: 45837 | Q12: HouseholdAccessories | R12: HouseholdAccessories | S12: Cash | T12: 150 | U12: fork spoon
B13: 45855 | D13: 500 | E13: SCB | F13: bKash | H13: =TEXT(I13, "dddd") -> Saturday | I13: 45843 | J13: {=sum(IF(($P$3:$P$100=I13), $T$3:$T$100, 0))} -> 0 | P13: 45836 | Q13: Bazar | R13: AdvGiven | S13: Cash | T13: 6000 | U13: ammu - 5k, sis - 1K
H14: =TEXT(I14, "dddd") -> Sunday | I14: 45844 | J14: {=sum(IF(($P$3:$P$100=I14), $T$3:$T$100, 0))} -> 17450 | P14: 45835 | Q14: Donation | R14: Donation | S14: Cash | T14: 10
H15: =TEXT(I15, "dddd") -> Monday | I15: 45845 | J15: {=sum(IF(($P$3:$P$100=I15), $T$3:$T$100, 0))} -> 20 | L15: LEND GIVEN TO | N15: =sum(N17:N22) -> 0 | P15: 45837 | Q15: Donation | R15: Unknown | S15: Cash | T15: 0 | U15: X
H16: =TEXT(I16, "dddd") -> Tuesday | I16: 45846 | J16: {=sum(IF(($P$3:$P$100=I16), $T$3:$T$100, 0))} -> 0 | L16: Date | M16: Given To | N16: Amount | P16: 45838 | Q16: Bazar | R16: Others | S16: Cash | T16: =180+10 -> 190 | U16: noodles
H17: =TEXT(I17, "dddd") -> Wednesday | I17: 45847 | J17: {=sum(IF(($P$3:$P$100=I17), $T$3:$T$100, 0))} -> 140 | L17: 45774 | M17: 2500 | N17: Rajib vai | P17: 45838 | Q17: Bazar | R17: DailyBazar | S17: Cash | T17: 195 | U17: cal
H18: =TEXT(I18, "dddd") -> Thursday | I18: 45848 | J18: {=sum(IF(($P$3:$P$100=I18), $T$3:$T$100, 0))} -> 0 | M18: 3000 | N18: Rafi vai | P18: 45839 | Q18: RentAndPaybill | R18: ElectricBill_Dhk | S18: Nagad | T18: 805
H19: =TEXT(I19, "dddd") -> Friday | I19: 45849 | J19: {=sum(IF(($P$3:$P$100=I19), $T$3:$T$100, 0))} -> 1678 | M19: 100 | N19: arafat vai | P19: 45839 | Q19: HouseholdAccessories | R19: HouseholdAccessories | S19: Cash | T19: =50+50 -> 100
H20: =TEXT(I20, "dddd") -> Saturday | I20: 45850 | J20: {=sum(IF(($P$3:$P$100=I20), $T$3:$T$100, 0))} -> 285 | P20: 45840 | Q20: Bazar | R20: Others | S20: Cash | T20: 200
H21: =TEXT(I21, "dddd") -> Sunday | I21: 45851 | J21: {=sum(IF(($P$3:$P$100=I21), $T$3:$T$100, 0))} -> 460 | P21: 45841 | Q21: Bazar | R21: Fruits | S21: Cash | T21: 400
H22: =TEXT(I22, "dddd") -> Monday | I22: 45852 | J22: {=sum(IF(($P$3:$P$100=I22), $T$3:$T$100, 0))} -> 200 | P22: 45841 | Q22: Bazar | R22: Others | S22: Cash | T22: 50
H23: =TEXT(I23, "dddd") -> Tuesday | I23: 45853 | J23: {=sum(IF(($P$3:$P$100=I23), $T$3:$T$100, 0))} -> 140 | P23: 45844 | Q23: RentAndPaybill | R23: HouseRent | S23: Cash | T23: 13000
H24: =TEXT(I24, "dddd") -> Wednesday | I24: 45854 | J24: {=sum(IF(($P$3:$P$100=I24), $T$3:$T$100, 0))} -> 210 | L24: LEND TAKEN FROM | N24: =sum(N26:N31) -> 0 | P24: 45844 | Q24: RentAndPaybill | R24: GassBill | S24: Cash | T24: 1080
H25: =TEXT(I25, "dddd") -> Thursday | I25: 45855 | J25: {=sum(IF(($P$3:$P$100=I25), $T$3:$T$100, 0))} -> 1220 | L25: Date | M25: Taken From | N25: Amount | P25: 45844 | Q25: RentAndPaybill | R25: ServiceBill | S25: Cash | T25: =600+200+20 -> 820
H26: =TEXT(I26, "dddd") -> Friday | I26: 45856 | J26: {=sum(IF(($P$3:$P$100=I26), $T$3:$T$100, 0))} -> 0 | P26: 45844 | Q26: Savings | R26: EximBank_2.5 | S26: SCB | T26: 2500 | U26: EXIM
H27: =TEXT(I27, "dddd") -> Saturday | I27: 45857 | J27: {=sum(IF(($P$3:$P$100=I27), $T$3:$T$100, 0))} -> 0 | P27: 45845 | Q27: ExtraExpenses | R27: Tea | S27: Cash | T27: 20
H28: =TEXT(I28, "dddd") -> Sunday | I28: 45858 | J28: {=sum(IF(($P$3:$P$100=I28), $T$3:$T$100, 0))} -> 420 | P28: 45847 | Q28: Bazar | R28: Others | S28: Cash | T28: 140
H29: =TEXT(I29, "dddd") -> Monday | I29: 45859 | J29: {=sum(IF(($P$3:$P$100=I29), $T$3:$T$100, 0))} -> 260 | P29: 45849 | Q29: Donation | R29: Donation | S29: Cash | T29: 10
H30: =TEXT(I30, "dddd") -> Tuesday | I30: 45860 | J30: {=sum(IF(($P$3:$P$100=I30), $T$3:$T$100, 0))} -> 670 | P30: 45849 | Q30: ExtraExpenses | R30: Travel | S30: Cash | T30: 30
H31: =TEXT(I31, "dddd") -> Wednesday | I31: 45861 | J31: {=sum(IF(($P$3:$P$100=I31), $T$3:$T$100, 0))} -> 100 | P31: 45849 | Q31: ExtraExpenses | R31: Tea | S31: Cash | T31: =30+60 -> 90
H32: =TEXT(I32, "dddd") -> Thursday | I32: 45862 | J32: {=sum(IF(($P$3:$P$100=I32), $T$3:$T$100, 0))} -> 536 | P32: 45849 | Q32: Bazar | R32: Fruits | S32: Cash | T32: =300+40 -> 340
H33: =TEXT(I33, "dddd") -> Friday | I33: 45863 | J33: {=sum(IF(($P$3:$P$100=I33), $T$3:$T$100, 0))} -> 1200 | N33: =sum(N35:N40) -> 0 | P33: 45849 | Q33: Bazar | R33: AdvGiven | S33: Cash | T33: 1000
H34: =TEXT(I34, "dddd") -> Saturday | I34: 45864 | J34: {=sum(IF(($P$3:$P$100=I34), $T$3:$T$100, 0))} -> 0 | P34: 45850 | Q34: HouseholdAccessories | R34: DailyAccessories | S34: Cash | T34: 40
H35: =TEXT(I35, "dddd") -> Sunday | I35: 45865 | J35: {=sum(IF(($P$3:$P$100=I35), $T$3:$T$100, 0))} -> 0 | P35: 45850 | Q35: Bazar | R35: Others | S35: Cash | T35: =45+200 -> 245
J36: {=sum(IF(($P$3:$P$100=I36), $T$3:$T$100, 0))} -> 0 | P36: 45851 | Q36: ExtraExpenses | R36: ExtraExpenses | S36: Cash | T36: 350 | U36: team
P37: 45851 | Q37: HouseholdAccessories | R37: Medicine | S37: Cash | T37: 90
P38: 45851 | Q38: Donation | R38: Donation | S38: Cash | T38: 20
P39: 45852 | Q39: Donation | R39: Donation | S39: Cash | T39: 200
P40: 45853 | Q40: Bazar | R40: Others | S40: Cash | T40: 140
P41: 45854 | Q41: Bazar | R41: Others | S41: Cash | T41: 160
...

Sheet Aug 25
B2: T r a n s a c t i o n & P a y | H2: DAY | I2: Date | J2: =sum(J4:J39) -> 41856 | L2: FINANCIAL STATUS | N2: =M4+M5+M8+M9 -> 21276 | P2: Date | Q2: Category | R2: Subcategory | S2: Payment Method | T2: Amount | U2: Remarks
B3: Date | C3: Cost | D3: Amount | E3: FROM | F3: TO | J3: Cost | L3: Type | M3: Current Status | N3: Start with | P3: 45864 | Q3: Bazar | R3: AdvGiven | S3: Cash | T3: 2000
B4: 45865 | D4: 39500 | E4: Add | F4: SCB | H4: =TEXT(I4, "dddd") -> Saturday | I4: 45864 | J4: {=sum(IF(($P$3:$P$100=I4), $T$3:$T$100, 0))} -> 2100 | L4: {=INDIRECT("Account")} -> Cash | M4: {=N4 - sum(IF(($E$4:$E$49=L4), $D$4:$D$39 + $C$4:$C$39, 0)) + sum(IF(($F$4:$F$49=L4), $D$4:$D$39, 0)) - sum(IF(($S$3:$S$100=L4), $T$3:$T$100, 0))} -> 4145 | N4: ='July 25'!M4 -> 3725 | P4: 45864 | Q4: Donation | R4: Donation | S4: Cash | T4: 20
B5: 45866 | D5: 1000 | E5: SCB | F5: bKash | H5: =TEXT(I5, "dddd") -> Sunday | I5: 45865 | J5: {=sum(IF(($P$3:$P$100=I5), $T$3:$T$100, 0))} -> 700 | L5: SCB | M5: {=N5 - sum(IF(($E$4:$E$49=L5), $D$4:$D$39 + $C$4:$C$39, 0)) + sum(IF(($F$4:$F$49=L5), $D$4:$D$39, 0)) - sum(IF(($S$3:$S$100=L5), $T$3:$T$100, 0))} -> 16704 | N5: ='July 25'!M5 -> 57034 | P5: 45864 | Q5: ExtraExpenses | R5: Tea | S5: Cash | T5: 60 | U5: resort
B6: 45866 | C6: 15 | D6: 10000 | E6: SBL | F6: Cash | H6: =TEXT(I6, "dddd") -> Monday | I6: 45866 | J6: {=sum(IF(($P$3:$P$100=I6), $T$3:$T$100, 0))} -> 1630 | L6: SBL | M6: {=N6 - sum(IF(($E$4:$E$49=L6), $D$4:$D$39 + $C$4:$C$39, 0)) + sum(IF(($F$4:$F$49=L6), $D$4:$D$39, 0)) - sum(IF(($S$3:$S$100=L6), $T$3:$T$100, 0))} -> 30176 | N6: ='July 25'!M6 -> 30191 | P6: 45865 | Q6: Donation | R6: Donation | S6: Cash | T6: 700 | U6: due clear to santo
B7: 45866 | D7: 2000 | E7: Cash | F7: City | H7: =TEXT(I7, "dddd") -> Tuesday | I7: 45867 | J7: {=sum(IF(($P$3:$P$100=I7), $T$3:$T$100, 0))} -> 5000 | L7: EXIM | M7: {=N7 - sum(IF(($E$4:$E$49=L7), $D$4:$D$39 + $C$4:$C$39, 0)) + sum(IF(($F$4:$F$49=L7), $D$4:$D$39, 0)) - sum(IF(($S$3:$S$100=L7), $T$3:$T$100, 0))} -> 285 | N7: ='July 25'!M7 -> 285 | P7: 45866 | Q7: RentAndPaybill | R7: ElectricBill_Dhk | S7: bKash | T7: 800
B8: 45866 | D8: 10000 | E8: SCB | F8: SBL | H8: =TEXT(I8, "dddd") -> Wednesday | I8: 45868 | J8: {=sum(IF(($P$3:$P$100=I8), $T$3:$T$100, 0))} -> 1476 | L8: bKash | M8: {=N8 - sum(IF(($E$4:$E$49=L8), $D$4:$D$39 + $C$4:$C$39, 0)) + sum(IF(($F$4:$F$49=L8), $D$4:$D$39, 0)) - sum(IF(($S$3:$S$100=L8), $T$3:$T$100, 0))} -> 425 | N8: ='July 25'!M8 -> 77 | P8: 45866 | Q8: MobileInternet | R8: ForOthers | S8: bKash | T8: 50
B9: 45868 | D9: 1000 | E9: SCB | F9: bKash | H9: =TEXT(I9, "dddd") -> Thursday | I9: 45869 | J9: {=sum(IF(($P$3:$P$100=I9), $T$3:$T$100, 0))} -> 0 | L9: Nagad | M9: {=N9 - sum(IF(($E$4:$E$49=L9), $D$4:$D$39 + $C$4:$C$39, 0)) + sum(IF(($F$4:$F$49=L9), $D$4:$D$39, 0)) - sum(IF(($S$3:$S$100=L9), $T$3:$T$100, 0))} -> 2 | N9: ='July 25'!M9 -> 2 | P9: 45866 | Q9: Bazar | R9: Fruits | S9: Cash | T9: 150 | U9: amra+peyara
B10: 45870 | D10: 2500 | E10: SCB | F10: EXIM | H10: =TEXT(I10, "dddd") -> Friday | I10: 45870 | J10: {=sum(IF(($P$3:$P$100=I10), $T$3:$T$100, 0))} -> 4375 | L10: LendTaken | M10: =N10-10000 -> 130000 | N10: ='July 25'!M10 -> 140000 | P10: 45866 | Q10: ExtraExpenses | R10: ExtraExpenses | S10: bKash | T10: 30
B11: 45873 | D11: 25000 | E11: SCB | F11: City | H11: =TEXT(I11, "dddd") -> Saturday | I11: 45871 | J11: {=sum(IF(($P$3:$P$100=I11), $T$3:$T$100, 0))} -> 80 | L11: LendGiven | M11: {=N11 - sum(IF(($E$4:$E$49=L11), $D$4:$D$39 + $C$4:$C$39, 0)) + sum(IF(($F$4:$F$49=L11), $D$4:$D$39, 0)) - sum(IF(($S$3:$S$100=L11), $T$3:$T$100, 0))} -> 5500 | N11: ='July 25'!M11 -> 5500 | P11: 45867 | Q11: Bazar | R11: AdvGiven | S11: Cash | T11: 5000
